Workbook

Sheet Profile
A1: SOCIAL PROFILE (V.2017-0) | D1: Value chain: | F1: food-flour
D2: Country : | E2: Chad
A3: Date last modif. | B3: 45868
A12: Domain | C12: Present profile | E12: Trend | F12: Previous profile | G12: =Register!H3 -> ../../20..
C13: Score level | D13: Count | F13: Score level | G13: Count | I13: Tr_score
A14: =Register!A5 -> 1. WORKING CONDITIONS | C14: =Register!C10 -> Not at all | D14: =Register!B10 -> 1.175 | E14: =Register!D10 -> ↑ | F14: =Register!I10 -> Not at all | G14: =Register!H10 -> 0 | I14: =Register!#REF! -> #REF!
A15: =Register!A11 -> 2. LAND & WATER RIGHTS | C15: =Register!C15 -> Moderate/Low | D15: =Register!B15 -> 2 | E15: =Register!D15 -> ↑ | F15: =Register!I15 -> Not at all | G15: =Register!H15 -> 0 | I15: =Register!#REF! -> #REF!
A16: =Register!A16 -> 3. GENDER EQUALITY | C16: =Register!C22 -> Moderate/Low | D16: =Register!B22 -> 1.5666667 | E16: =Register!D22 -> ↑ | F16: =Register!I22 -> Not at all | G16: =Register!H22 -> 0 | I16: =Register!#REF! -> #REF!
A17: =Register!A23 -> 4. FOOD AND NUTRITION SECURITY | C17: =Register!C28 -> Moderate/Low | D17: =Register!B28 -> 1.625 | E17: =Register!D28 -> ↑ | F17: =Register!I28 -> Not at all | G17: =Register!H28 -> 0 | I17: =Register!#REF! -> #REF!
A18: =Register!A29 -> 5. SOCIAL CAPITAL | C18: =Register!C33 -> Moderate/Low | D18: =Register!B33 -> 2.3333333 | E18: =Register!D33 -> ↑ | F18: =Register!I33 -> Not at all | G18: =Register!H33 -> 0
A19: =Register!A34 -> 6. LIVING CONDITIONS | C19: =Register!C39 -> Not at all | D19: =Register!B39 -> 1.3333333 | E19: =Register!D39 -> ↑ | F19: =Register!I39 -> Not at all | G19: =Register!H39 -> 0 | I19: =Register!#REF! -> #REF!
I20: =AVERAGE(I14:I19) -> #REF!
A21: Overall Recommendation
A24: Major Issues
A26: Risk/Cost of Non-Intervention vs. Benefits
A28: Key Mitigating Measures

Sheet Register
A1: =Profile!F1 -> food-flour | C1: Country: | D1: =Profile!E2 -> Chad | F1: Date Last Modification: | G1: =Profile!B3 -> 45868 | H1: Previous Analysis
A2: Dimension | B2: Count | C2: Score level | D2: Trend | E2: Major risks and possible negative consequences | F2: Mitigating measures | G2: Comments | H2: date:
H3: ../../20.. | L3: =Questionnaire!$N$3 -> High | M3: Zero
H4: Score | I4: Level | L4: =Questionnaire!$N$4 -> Substantial | M4: Low
A5: =Questionnaire!$A$3 -> 1. WORKING CONDITIONS | L5: =Questionnaire!$N$5 -> Moderate/Low | M5: Medium
A6: =Questionnaire!$A$4 -> 1.1 Respect of labour rights | B6: =Questionnaire!J10 -> 1.2 | C6: =IF(B6<1.5,$L$6,IF(B6<2.5,$L$5,IF(B6<3.5,$L$4,IF(B6<4.5,$L$3,"n/a")))) -> Not at all | D6: =IF(H6<B6,"↑",IF(H6>B6,"↓","↔")) -> ↑ | E6: Reproduction des inégalités, accaparement valeur ajoutée, grande pauvreté des acteurs aval (meunier et préparatrices) signifiant risques de morbidité, faible espérance de vie, conditions de vie très difficiles. Impact nutritionnel pour les consommateurs en général (conditions nutri et sanitaires des bouillies) | H6: 0 | I6: =IF(H6<1.5,$L$6,IF(H6<2.5,$L$5,IF(H6<3.5,$L$4,IF(H6<4.5,$L$3,"n/a")))) -> Not at all | K6: ↑ | L6: =Questionnaire!$N$6 -> Not at all | M6: High
A7: =Questionnaire!$A$11 -> 1.2 Child Labour | B7: =Questionnaire!J14 -> 1.5 | C7: =IF(B7<1.5,$L$6,IF(B7<2.5,$L$5,IF(B7<3.5,$L$4,IF(B7<4.5,$L$3,"n/a")))) -> Moderate/Low | D7: =IF(H7<B7,"↑",IF(H7>B7,"↓","↔")) -> ↑ | E7: manque de formation et risques de santé | H7: 0 | I7: =IF(H7<1.5,$L$6,IF(H7<2.5,$L$5,IF(H7<3.5,$L$4,IF(H7<4.5,$L$3,"n/a")))) -> Not at all | K7: ↓ | L7: =Questionnaire!$N$7 -> n/a
A8: =Questionnaire!$A$15 -> 1.3 Job safety | B8: =Questionnaire!J17 -> 1 | C8: =IF(B8<1.5,$L$6,IF(B8<2.5,$L$5,IF(B8<3.5,$L$4,IF(B8<4.5,$L$3,"n/a")))) -> Not at all | D8: =IF(H8<B8,"↑",IF(H8>B8,"↓","↔")) -> ↑ | E8: Reproduction des inégalités, accaparement valeur ajoutée, grande pauvreté des acteurs aval (meunier et préparatrices), impact nutritionnel pour les consommateurs en général (conditions nutri et sanitaires des bouillies) | H8: 0 | I8: =IF(H8<1.5,$L$6,IF(H8<2.5,$L$5,IF(H8<3.5,$L$4,IF(H8<4.5,$L$3,"n/a")))) -> Not at all | K8: ↔
A9: =Questionnaire!$A$18 -> 1.4 Attractiveness | B9: =Questionnaire!J21 -> 1 | C9: =IF(B9<1.5,$L$6,IF(B9<2.5,$L$5,IF(B9<3.5,$L$4,IF(B9<4.5,$L$3,"n/a")))) -> Not at all | D9: =IF(H9<B9,"↑",IF(H9>B9,"↓","↔")) -> ↑ | H9: 0 | I9: =IF(H9<1.5,$L$6,IF(H9<2.5,$L$5,IF(H9<3.5,$L$4,IF(H9<4.5,$L$3,"n/a")))) -> Not at all
A10: Average | B10: =IF(COUNT(B6:B9)=0,"n/a",(AVERAGE(B6:B9))) -> 1.175 | C10: =IF(B10<1.5,$L$6,IF(B10<2.5,$L$5,IF(B10<3.5,$L$4,IF(B10<4.5,$L$3,"n/a")))) -> Not at all | D10: =IF(H10<B10,"↑",IF(H10>B10,"↓","↔")) -> ↑ | H10: =AVERAGE(H6:H9) -> 0 | I10: =IF(H10<1.5,$L$6,IF(H10<2.5,$L$5,IF(H10<3.5,$L$4,IF(H10<4.5,$L$3,"n/a")))) -> Not at all
A11: =Questionnaire!$A$22 -> 2. LAND & WATER RIGHTS
A12: =Questionnaire!$A$23 -> 2.1 Adherence to VGGT | B12: =Questionnaire!J26 -> 3 | C12: =IF(B12<1.5,$L$6,IF(B12<2.5,$L$5,IF(B12<3.5,$L$4,IF(B12<4.5,$L$3,"n/a")))) -> Substantial | D12: =IF(H12<B12,"↑",IF(H12>B12,"↓","↔")) -> ↑ | H12: 0 | I12: =IF(H12<1.5,$L$6,IF(H12<2.5,$L$5,IF(H12<3.5,$L$4,IF(H12<4.5,$L$3,"n/a")))) -> Not at all
A13: =Questionnaire!$A$27 -> 2.2 Transparency, participation and consultation | B13: =Questionnaire!J32 -> 1 | C13: =IF(B13<1.5,$L$6,IF(B13<2.5,$L$5,IF(B13<3.5,$L$4,IF(B13<4.5,$L$3,"n/a")))) -> Not at all | D13: =IF(H13<B13,"↑",IF(H13>B13,"↓","↔")) -> ↑ | E13: Reproduction des inégalités, accaparement valeur ajoutée, pauvreté et manque de développement | H13: 0 | I13: =IF(H13<1.5,$L$6,IF(H13<2.5,$L$5,IF(H13<3.5,$L$4,IF(H13<4.5,$L$3,"n/a")))) -> Not at all
A14: =Questionnaire!$A$33 -> 2.3 Equity,compensation and justice | B14: =Questionnaire!J38 -> n/a | C14: =IF(B14<1.5,$L$6,IF(B14<2.5,$L$5,IF(B14<3.5,$L$4,IF(B14<4.5,$L$3,"n/a")))) -> n/a | D14: =IF(H14<B14,"↑",IF(H14>B14,"↓","↔")) -> ↑ | H14: 0 | I14: =IF(H14<1.5,$L$6,IF(H14<2.5,$L$5,IF(H14<3.5,$L$4,IF(H14<4.5,$L$3,"n/a")))) -> Not at all
A15: Average | B15: =IF(COUNT(B12:B14)=0,"n/a",(AVERAGE(B12:B14))) -> 2 | C15: =IF(B15<1.5,$L$6,IF(B15<2.5,$L$5,IF(B15<3.5,$L$4,IF(B15<4.5,$L$3,"n/a")))) -> Moderate/Low | D15: =IF(H15<B15,"↑",IF(H15>B15,"↓","↔")) -> ↑ | H15: =AVERAGE(H12:H14) -> 0 | I15: =IF(H15<1.5,$L$6,IF(H15<2.5,$L$5,IF(H15<3.5,$L$4,IF(H15<4.5,$L$3,"n/a")))) -> Not at all
A16: =Questionnaire!$A$39 -> 3. GENDER EQUALITY
A17: =Questionnaire!$A$40 -> 3.1 Economic activities | B17: =Questionnaire!J43 -> 2.5 | C17: =IF(B17<1.5,$L$6,IF(B17<2.5,$L$5,IF(B17<3.5,$L$4,IF(B17<4.5,$L$3,"n/a")))) -> Substantial | D17: =IF(H17<B17,"↑",IF(H17>B17,"↓","↔")) -> ↑ | H17: 0 | I17: =IF(H17<1.5,$L$6,IF(H17<2.5,$L$5,IF(H17<3.5,$L$4,IF(H17<4.5,$L$3,"n/a")))) -> Not at all
A18: =Questionnaire!$A$44 -> 3.2 Access to resources and services | B18: =Questionnaire!J49 -> 1 | C18: =IF(B18<1.5,$L$6,IF(B18<2.5,$L$5,IF(B18<3.5,$L$4,IF(B18<4.5,$L$3,"n/a")))) -> Not at all | D18: =IF(H18<B18,"↑",IF(H18>B18,"↓","↔")) -> ↑ | E18: Reproduction des inégalités, accaparement valeur ajoutée, grande pauvreté des acteurs aval (détaillantes et préparatrices), signifiant risques de morbidité, faible espérance de vie, conditions de vie très difficiles. Impact nutritionnel pour les consommateurs en général (conditions nutri et sanitaires des bouillies aliments de rue. | H18: 0 | I18: =IF(H18<1.5,$L$6,IF(H18<2.5,$L$5,IF(H18<3.5,$L$4,IF(H18<4.5,$L$3,"n/a")))) -> Not at all
A19: =Questionnaire!$A$50 -> 3.3 Decision making | B19: =Questionnaire!J56 -> 2 | C19: =IF(B19<1.5,$L$6,IF(B19<2.5,$L$5,IF(B19<3.5,$L$4,IF(B19<4.5,$L$3,"n/a")))) -> Moderate/Low | D19: =IF(H19<B19,"↑",IF(H19>B19,"↓","↔")) -> ↑ | E19: Reproduction des inégalités, accaparement valeur ajoutée, grande pauvreté des acteurs aval (détaillantes et préparatrices), signifiant risques de morbidité, faible espérance de vie, conditions de vie très difficiles. Impact nutritionnel pour les consommateurs en général (conditions nutri et sanitaires des bouillies aliments de rue. | H19: 0 | I19: =IF(H19<1.5,$L$6,IF(H19<2.5,$L$5,IF(H19<3.5,$L$4,IF(H19<4.5,$L$3,"n/a")))) -> Not at all
A20: =Questionnaire!$A$57 -> 3.4 Leadership and empowerment | B20: =Questionnaire!J62 -> 1.3333333 | C20: =IF(B20<1.5,$L$6,IF(B20<2.5,$L$5,IF(B20<3.5,$L$4,IF(B20<4.5,$L$3,"n/a")))) -> Not at all | D20: =IF(H20<B20,"↑",IF(H20>B20,"↓","↔")) -> ↑ | E20: idem | H20: 0 | I20: =IF(H20<1.5,$L$6,IF(H20<2.5,$L$5,IF(H20<3.5,$L$4,IF(H20<4.5,$L$3,"n/a")))) -> Not at all
A21: =Questionnaire!$A$63 -> 3.5 Hardship and division of labour | B21: =Questionnaire!J66 -> 1 | C21: =IF(B21<1.5,$L$6,IF(B21<2.5,$L$5,IF(B21<3.5,$L$4,IF(B21<4.5,$L$3,"n/a")))) -> Not at all | D21: =IF(H21<B21,"↑",IF(H21>B21,"↓","↔")) -> ↑ | E21: idem | H21: 0 | I21: =IF(H21<1.5,$L$6,IF(H21<2.5,$L$5,IF(H21<3.5,$L$4,IF(H21<4.5,$L$3,"n/a")))) -> Not at all
A22: Average | B22: =IF(COUNT(B17:B21)=0,"n/a",(AVERAGE(B17:B21))) -> 1.5666667 | C22: =IF(B22<1.5,$L$6,IF(B22<2.5,$L$5,IF(B22<3.5,$L$4,IF(B22<4.5,$L$3,"n/a")))) -> Moderate/Low | D22: =IF(H22<B22,"↑",IF(H22>B22,"↓","↔")) -> ↑ | H22: =AVERAGE(H17:H21) -> 0 | I22: =IF(H22<1.5,$L$6,IF(H22<2.5,$L$5,IF(H22<3.5,$L$4,IF(H22<4.5,$L$3,"n/a")))) -> Not at all
A23: =Questionnaire!$A$67 -> 4. FOOD AND NUTRITION SECURITY
A24: =Questionnaire!$A$68 -> 4.1 Availability of food | B24: =Questionnaire!J71 -> 2 | C24: =IF(B24<1.5,$L$6,IF(B24<2.5,$L$5,IF(B24<3.5,$L$4,IF(B24<4.5,$L$3,"n/a")))) -> Moderate/Low | D24: =IF(H24<B24,"↑",IF(H24>B24,"↓","↔")) -> ↑ | E24: Selon études du coût de la faim par le Ministère du Plan et le PAM (avant restrictions USAID 2025), la malnutrition au Tchad convertie en points de PIB diminue celui-ci de 10% et provoque 30% du redoublement des classes. Mais surtout; retards de croissance, baisse niveau et espérance de vie. | H24: 0 | I24: =IF(H24<1.5,$L$6,IF(H24<2.5,$L$5,IF(H24<3.5,$L$4,IF(H24<4.5,$L$3,"n/a")))) -> Not at all
A25: =Questionnaire!$A$72 -> 4.2 Accessibility of food | B25: =Questionnaire!J75 -> 2 | C25: =IF(B25<1.5,$L$6,IF(B25<2.5,$L$5,IF(B25<3.5,$L$4,IF(B25<4.5,$L$3,"n/a")))) -> Moderate/Low | D25: =IF(H25<B25,"↑",IF(H25>B25,"↓","↔")) -> ↑ | E25: idem | H25: 0 | I25: =IF(H25<1.5,$L$6,IF(H25<2.5,$L$5,IF(H25<3.5,$L$4,IF(H25<4.5,$L$3,"n/a")))) -> Not at all
A26: =Questionnaire!$A$76 -> 4.3 Utilisation and nutritional adequacy | B26: =Questionnaire!J80 -> 1 | C26: =IF(B26<1.5,$L$6,IF(B26<2.5,$L$5,IF(B26<3.5,$L$4,IF(B26<4.5,$L$3,"n/a")))) -> Not at all | D26: =IF(H26<B26,"↑",IF(H26>B26,"↓","↔")) -> ↑ | E26: transition nutritionnelle néfaste pour de nombreux jeunes travailleurs urbains (clients) | H26: 0 | I26: =IF(H26<1.5,$L$6,IF(H26<2.5,$L$5,IF(H26<3.5,$L$4,IF(H26<4.5,$L$3,"n/a")))) -> Not at all
A27: =Questionnaire!$A$81 -> 4.4 Stability | B27: =Questionnaire!J84 -> 1.5 | C27: =IF(B27<1.5,$L$6,IF(B27<2.5,$L$5,IF(B27<3.5,$L$4,IF(B27<4.5,$L$3,"n/a")))) -> Moderate/Low | D27: =IF(H27<B27,"↑",IF(H27>B27,"↓","↔")) -> ↑ | E27: idem | H27: 0 | I27: =IF(H27<1.5,$L$6,IF(H27<2.5,$L$5,IF(H27<3.5,$L$4,IF(H27<4.5,$L$3,"n/a")))) -> Not at all
A28: Average | B28: =IF(COUNT(B24:B27)=0,"n/a",(AVERAGE(B24:B27))) -> 1.625 | C28: =IF(B28<1.5,$L$6,IF(B28<2.5,$L$5,IF(B28<3.5,$L$4,IF(B28<4.5,$L$3,"n/a")))) -> Moderate/Low | D28: =IF(H28<B28,"↑",IF(H28>B28,"↓","↔")) -> ↑ | H28: =AVERAGE(H24:H27) -> 0 | I28: =IF(H28<1.5,$L$6,IF(H28<2.5,$L$5,IF(H28<3.5,$L$4,IF(H28<4.5,$L$3,"n/a")))) -> Not at all
A29: =Questionnaire!$A$85 -> 5. SOCIAL CAPITAL
A30: =Questionnaire!$A$86 -> 5.1 Strength of producer organisations | B30: =Questionnaire!J91 -> n/a | C30: =IF(B30<1.5,$L$6,IF(B30<2.5,$L$5,IF(B30<3.5,$L$4,IF(B30<4.5,$L$3,"n/a")))) -> n/a | D30: =IF(H30<B30,"↑",IF(H30>B30,"↓","↔")) -> ↑ | H30: 0 | I30: =IF(H30<1.5,$L$6,IF(H30<2.5,$L$5,IF(H30<3.5,$L$4,IF(H30<4.5,$L$3,"n/a")))) -> Not at all
A31: =Questionnaire!$A$92 -> 5.2 Information and confidence | B31: =Questionnaire!J95 -> 3 | C31: =IF(B31<1.5,$L$6,IF(B31<2.5,$L$5,IF(B31<3.5,$L$4,IF(B31<4.5,$L$3,"n/a")))) -> Substantial | D31: =IF(H31<B31,"↑",IF(H31>B31,"↓","↔")) -> ↑ | H31: 0 | I31: =IF(H31<1.5,$L$6,IF(H31<2.5,$L$5,IF(H31<3.5,$L$4,IF(H31<4.5,$L$3,"n/a")))) -> Not at all
A32: =Questionnaire!$A$96 -> 5.3 Social involvement | B32: =Questionnaire!J100 -> 1.6666667 | C32: =IF(B32<1.5,$L$6,IF(B32<2.5,$L$5,IF(B32<3.5,$L$4,IF(B32<4.5,$L$3,"n/a")))) -> Moderate/Low | D32: =IF(H32<B32,"↑",IF(H32>B32,"↓","↔")) -> ↑ | E32: Reproduction des inégalités, accaparement valeur ajoutée, pauvreté et manque de développement | H32: 0 | I32: =IF(H32<1.5,$L$6,IF(H32<2.5,$L$5,IF(H32<3.5,$L$4,IF(H32<4.5,$L$3,"n/a")))) -> Not at all
A33: Average | B33: =IF(COUNT(B30:B32)=0,"n/a",(AVERAGE(B30:B32))) -> 2.3333333 | C33: =IF(B33<1.5,$L$6,IF(B33<2.5,$L$5,IF(B33<3.5,$L$4,IF(B33<4.5,$L$3,"n/a")))) -> Moderate/Low | D33: =IF(H33<B33,"↑",IF(H33>B33,"↓","↔")) -> ↑ | H33: =AVERAGE(H30:H32) -> 0 | I33: =IF(H33<1.5,$L$6,IF(H33<2.5,$L$5,IF(H33<3.5,$L$4,IF(H33<4.5,$L$3,"n/a")))) -> Not at all
A34: =Questionnaire!$A$101 -> 6. LIVING CONDITIONS
A35: =Questionnaire!$A$102 -> 6.1 Health services | B35: =Questionnaire!J106 -> 1.3333333 | C35: =IF(B35<1.5,$L$6,IF(B35<2.5,$L$5,IF(B35<3.5,$L$4,IF(B35<4.5,$L$3,"n/a")))) -> Not at all | D35: =IF(H35<B35,"↑",IF(H35>B35,"↓","↔")) -> ↑ | E35: il suffit de voir les indicateurs: espérance de vie 54 ans en 2023 ; mortalité infantile très élevée: 95 /1000 ; dont 40 à 50 néonatale. Les préparatrices font partie des très pauvres. | H35: 0 | I35: =IF(H35<1.5,$L$6,IF(H35<2.5,$L$5,IF(H35<3.5,$L$4,IF(H35<4.5,$L$3,"n/a")))) -> Not at all
A36: =Questionnaire!$A$107 -> 6.2 Housing | B36: =Questionnaire!J110 -> 1 | C36: =IF(B36<1.5,$L$6,IF(B36<2.5,$L$5,IF(B36<3.5,$L$4,IF(B36<4.5,$L$3,"n/a")))) -> Not at all | D36: =IF(H36<B36,"↑",IF(H36>B36,"↓","↔")) -> ↑ | E36: idem | H36: 0 | I36: =IF(H36<1.5,$L$6,IF(H36<2.5,$L$5,IF(H36<3.5,$L$4,IF(H36<4.5,$L$3,"n/a")))) -> Not at all
A37: =Questionnaire!$A$111 -> 6.3 Education and training | B37: =Questionnaire!J115 -> 1.6666667 | C37: =IF(B37<1.5,$L$6,IF(B37<2.5,$L$5,IF(B37<3.5,$L$4,IF(B37<4.5,$L$3,"n/a")))) -> Moderate/Low | D37: =IF(H37<B37,"↑",IF(H37>B37,"↓","↔")) -> ↑ | E37: idem. Reproduction des inégalités par souc de protection du futur. (scolarisation ) | H37: 0 | I37: =IF(H37<1.5,$L$6,IF(H37<2.5,$L$5,IF(H37<3.5,$L$4,IF(H37<4.5,$L$3,"n/a")))) -> Not at all
A38: =Questionnaire!$A$116 -> 6.4 Mobility ?????? | B38: =Questionnaire!J120 -> n/a | C38: =IF(B38<1.5,$L$6,IF(B38<2.5,$L$5,IF(B38<3.5,$L$4,IF(B38<4.5,$L$3,"n/a")))) -> n/a | D38: =IF(H38<B38,"↑",IF(H38>B38,"↓","↔")) -> ↑ | H38: 0 | I38: =IF(H38<1.5,$L$6,IF(H38<2.5,$L$5,IF(H38<3.5,$L$4,IF(H38<4.5,$L$3,"n/a")))) -> Not at all
A39: Average | B39: =IF(COUNT(B35:B38)=0,"n/a",(AVERAGE(B35:B38))) -> 1.3333333 | C39: =IF(B39<1.5,$L$6,IF(B39<2.5,$L$5,IF(B39<3.5,$L$4,IF(B39<4.5,$L$3,"n/a")))) -> Not at all | D39: =IF(H39<B39,"↑",IF(H39>B39,"↓","↔")) -> ↑ | H39: =AVERAGE(H35:H38) -> 0 | I39: =IF(H39<1.5,$L$6,IF(H39<2.5,$L$5,IF(H39<3.5,$L$4,IF(H39<4.5,$L$3,"n/a")))) -> Not at all

Sheet Questionnaire
A1: Value chain: | B1: =Profile!F1 -> food-flour | C1: Country: | D1: =Profile!E2 -> Chad | F1: Date Last Modification: | J1: =Profile!B3 -> 45868 | L1: Explanations
A2: Question | C2: Source | D2: Score level | E2: Count | F2: Comments
A3: 1. WORKING CONDITIONS | N3: High | O3: 4.5
A4: 1.1 Respect of labour rights | N4: Substantial | O4: 3.5
A5: 1.1.1 To what extent do companies involved in the value chain respect the standards elaborated in the 8 fundamental ILO international labour conventions and in the ICESCR and ICCPR? | D5: Moderate/Low | E5: =IF(D5=$N$6,1,IF(D5=$N$5,2,IF(D5=$N$4,3,IF(D5=$N$3,4,"n/a")))) -> 2 | F5: Le Code du Travail tchadien tend à l'égalité, mais certaines dispositions historiques ou interprétations peuvent induire des inégalités. Égalité de traitement : Le Code du Travail, en principe, ne fait pas de distinction de sexe en matière de droits et de devoirs, d'accès à l'emploi et de conditions de travail. Protections spécifiques : Certaines dispositions peuvent être vues comme protectrices mais aussi restrictives, comme l'interdiction du travail de nuit pour les femmes (Article 205). Bien que visant à protéger, cela peut limiter les opportunités d'emploi pour les femmes dans certains secteurs. Rémunération : La loi n°2006-340 du 23 mars 2006 relative à l'égalité salariale entre les femmes et les hommes vise à garantir l'égalité de rémunération pour un travail de valeur égale. Dans la pratique de la SCV B, les acteurs (grossistes détaillants meuniers préparatrices) ignorent les standards | N5: Moderate/Low | O5: 2.5
A6: 1.1.2 Is freedom of association allowed and effective (collective bargaining)? | D6: Not at all | E6: =IF(D6=$N$6,1,IF(D6=$N$5,2,IF(D6=$N$4,3,IF(D6=$N$3,4,"n/a")))) -> 1 | F6: organisation sociale/familiale du commerce ; travail isolé non représenté ni défendu des acteurs de l'aval (détaillants, meuniers préparatrices) | N6: Not at all | O6: 1.5
A7: 1.1.3 To what extent do workers benefit from enforceable and fair contracts | D7: Not at all | E7: =IF(D7=$N$6,1,IF(D7=$N$5,2,IF(D7=$N$4,3,IF(D7=$N$3,4,"n/a")))) -> 1 | F7: organisation sociale/familiale du commerce ; travail isolé non représenté ni défendu des acteurs de l'aval (détaillants, meuniers préparatrices) | N7: n/a
A8: 1.1.4 To what extent are risks of forced labour in any segment of the value chain minimised? | D8: Not at all | E8: =IF(D8=$N$6,1,IF(D8=$N$5,2,IF(D8=$N$4,3,IF(D8=$N$3,4,"n/a")))) -> 1 | F8: organisation sociale/familiale du commerce ; travail isolé non représenté ni défendu des acteurs de l'aval (détaillants, meuniers préparatrices)
A9: 1.1.5 To what extent are any risks of discrimination in employment for specific categories of the population minimised? | D9: Not at all | E9: =IF(D9=$N$6,1,IF(D9=$N$5,2,IF(D9=$N$4,3,IF(D9=$N$3,4,"n/a")))) -> 1 | F9: Secteurs rémunérateurs et positions hiérarchiques (commerce, transport) sont détenus 1) par des hommes et 2) par des groupes/clans sociaux (ex: dans le Mayo kebbi, Gurane et Kanembous). Exclusion des autres. (Plutôt accaparement que exclusion)
C10: Average: | D10: =IF(E10<1.5,$N$6,IF(E10<2.5,$N$5,IF(E10<3.5,$N$4,IF(E10<4.5,$N$3,"n/a")))) -> Not at all | E10: =IF(COUNT(E5:E9)=0,"n/a",AVERAGE(E5:E9)) -> 1.2 | F10: =E10 -> 1.2 | H10: Final: | I10: =D10 -> Not at all | J10: =IF(I10=$N$7,"n/a",IF(AND(I10=$N$5,D10=$N$6),1.5,IF(AND(I10=$N$4,D10=$N$5),2.5,IF(AND(I10=$N$3,D10=$N$4),3.5,IF(AND(I10=$N$6,D10=$N$5),1.49,IF(AND(I10=$N$5,D10=$N$4),2.49,IF(AND(I10=$N$4,D10=$N$3),3.49,E10))))))) -> 1.2 | K10: Justification if adjustment of the score level = …
A11: 1.2 Child Labour
A12: 1.2.1 Degree of school attendance in case children are working (in any segment of the value chain)? | D12: Moderate/Low | E12: =IF(D12=$N$6,1,IF(D12=$N$5,2,IF(D12=$N$4,3,IF(D12=$N$3,4,"n/a")))) -> 2 | F12: quelques enfants aident ponctuellement. Population défavorisée, tx de scolarisation faible en particulier pour les filles (assignées à l'aide ménagère et au mariage) | L12: Cf: Guidance
A13: 1.2.2 Are children protected from exposure to harmful jobs? | D13: Not at all | E13: =IF(D13=$N$6,1,IF(D13=$N$5,2,IF(D13=$N$4,3,IF(D13=$N$3,4,"n/a")))) -> 1 | F13: Please add justification. | L13: Cf: Guidance
C14: Average: | D14: =IF(E14<1.5,$N$6,IF(E14<2.5,$N$5,IF(E14<3.5,$N$4,IF(E14<4.5,$N$3,"n/a")))) -> Moderate/Low | E14: =IF(COUNT(E12:E13)=0,"n/a",AVERAGE(E12:E13)) -> 1.5 | F14: =E14 -> 1.5 | H14: Final: | I14: =D14 -> Moderate/Low | J14: =IF(I14=$N$7,"n/a",IF(AND(I14=$N$5,D14=$N$6),1.5,IF(AND(I14=$N$4,D14=$N$5),2.5,IF(AND(I14=$N$3,D14=$N$4),3.5,IF(AND(I14=$N$6,D14=$N$5),1.49,IF(AND(I14=$N$5,D14=$N$4),2.49,IF(AND(I14=$N$4,D14=$N$3),3.49,E14))))))) -> 1.5 | K14: Justification if adjustment of the score level = …
A15: 1.3 Job safety
A16: 1.3.1 Degree of protection from accidents and health damages (in any segment of the value chain)? | D16: Not at all | E16: =IF(D16=$N$6,1,IF(D16=$N$5,2,IF(D16=$N$4,3,IF(D16=$N$3,4,"n/a")))) -> 1 | F16: Tous segments en dehors des règlements. Secteur du commerce et des transports, lucratif, très fermé, et secteur aval (mouture, préparation) très précaire et peu rémunérateur.
C17: Average: | D17: =IF(E17<1.5,$N$6,IF(E17<2.5,$N$5,IF(E17<3.5,$N$4,IF(E17<4.5,$N$3,"n/a")))) -> Not at all | E17: =IF(COUNT(E16)=0,"n/a",AVERAGE(E16)) -> 1 | F17: =E17 -> 1 | H17: Final: | I17: =D17 -> Not at all | J17: =IF(I17=$N$7,"n/a",IF(AND(I17=$N$5,D17=$N$6),1.5,IF(AND(I17=$N$4,D17=$N$5),2.5,IF(AND(I17=$N$3,D17=$N$4),3.5,IF(AND(I17=$N$6,D17=$N$5),1.49,IF(AND(I17=$N$5,D17=$N$4),2.49,IF(AND(I17=$N$4,D17=$N$3),3.49,E17))))))) -> 1 | K17: Justification if adjustment of the score level = …
A18: 1.4 Attractiveness
A19: 1.4.1 To what extent are remunerations in accordance with local standards? | D19: Not at all | E19: =IF(D19=$N$6,1,IF(D19=$N$5,2,IF(D19=$N$4,3,IF(D19=$N$3,4,"n/a")))) -> 1 | F19: subsistance | L19: Cf: Guidance
A20: 1.4.2 Are conditions of activities attractive for youth? | D20: Not at all | E20: =IF(D20=$N$6,1,IF(D20=$N$5,2,IF(D20=$N$4,3,IF(D20=$N$3,4,"n/a")))) -> 1 | F20: pure susbsistance, emplois ponctuels.
C21: Average: | D21: =IF(E21<1.5,$N$6,IF(E21<2.5,$N$5,IF(E21<3.5,$N$4,IF(E21<4.5,$N$3,"n/a")))) -> Not at all | E21: =IF(COUNT(E19:E20)=0,"n/a",AVERAGE(E19:E20)) -> 1 | F21: =E21 -> 1 | H21: Final: | I21: =D21 -> Not at all | J21: =IF(I21=$N$7,"n/a",IF(AND(I21=$N$5,D21=$N$6),1.5,IF(AND(I21=$N$4,D21=$N$5),2.5,IF(AND(I21=$N$3,D21=$N$4),3.5,IF(AND(I21=$N$6,D21=$N$5),1.49,IF(AND(I21=$N$5,D21=$N$4),2.49,IF(AND(I21=$N$4,D21=$N$3),3.49,E21))))))) -> 1 | K21: Justification if adjustment of the score level = …
A22: 2. LAND & WATER RIGHTS
A23: 2.1 Adherence to VGGT | L23: Cf: Guidance
A24: 2.1.1 Do the companies/institutions involved in the value chain declare adhering to the VGGT? | D24: Substantial | E24: =IF(D24=$N$6,1,IF(D24=$N$5,2,IF(D24=$N$4,3,IF(D24=$N$3,4,"n/a")))) -> 3 | F24: Le Tchad n’a pas formellement "adhéré" aux VGGT (car ces directives ne font pas l’objet d’une ratification formelle : elles sont volontaires). Mais elles sont intégrées dans la formulation de sa politique nationale foncière, avec des pgms de formation des acteurs, consultation citoyenne, validation politique et mise en œuvre de projets pilotés avec l’appui de la FAO, selon le modèle des VGGT. Le 10 novembre 2023 à N’Djamena, le Tchad a validé officiellement sa politique foncière nationale, résultat d’un processus participatif incluant gouvernement, société civile, communautés pastorales, femmes, jeunes, chefs traditionnels, etc.Ce document fonde sa vision stratégique sur les principes recommandés par les VGGT. Toutefois, le droit appliqué repose largement sur le droit coutumier qui désavantage les femmes. | L24: Cf: Guidance
A25: 2.1.2 If large scale investments for land aquisition are at stake, do the involved companies/institutions apply the 'Guide to due diligence of agribusiness projects that affect land and property rights'? | D25: n/a | E25: =IF(D25=$N$6,1,IF(D25=$N$5,2,IF(D25=$N$4,3,IF(D25=$N$3,4,"n/a")))) -> n/a | F25: non pertinent ici
C26: Average: | D26: =IF(E26<1.5,"Low",IF(E26<2.5,"Moderate",IF(E26<3.5,"Substantial",IF(E26<4.5,"High","n/a")))) -> Substantial | E26: =IF(COUNT(E24:E25)=0,"n/a",AVERAGE(E24:E25)) -> 3 | F26: =E26 -> 3 | H26: Final: | I26: =D26 -> Substantial | J26: =IF(I26=$N$7,"n/a",IF(AND(I26=$N$5,D26=$N$6),1.5,IF(AND(I26=$N$4,D26=$N$5),2.5,IF(AND(I26=$N$3,D26=$N$4),3.5,IF(AND(I26=$N$6,D26=$N$5),1.49,IF(AND(I26=$N$5,D26=$N$4),2.49,IF(AND(I26=$N$4,D26=$N$3),3.49,E26))))))) -> 3 | K26: Justification if adjustment of the score level = …
A27: 2.2 Transparency, participation and consultation
A28: 2.2.1 Level of prior disclosure of project related information to local stakeholders? | D28: n/a | E28: =IF(D28=$N$6,1,IF(D28=$N$5,2,IF(D28=$N$4,3,IF(D28=$N$3,4,"n/a")))) -> n/a | F28: Please add justification.
A29: 2.2.2 Level of accessibility of intervention policies, laws, procedures and decisions to all stakeholders of the value chain? | D29: Not at all | E29: =IF(D29=$N$6,1,IF(D29=$N$5,2,IF(D29=$N$4,3,IF(D29=$N$3,4,"n/a")))) -> 1 | F29: Please add justification.
A30: 2.2.3 Level of participation and consultation of all individuals and groups in the decision-making process? | D30: Not at all | E30: =IF(D30=$N$6,1,IF(D30=$N$5,2,IF(D30=$N$4,3,IF(D30=$N$3,4,"n/a")))) -> 1 | F30: Please add justification.
A31: 2.2.4 To what extent prior consent of those affected by the decisions was reached? | D31: Not at all | E31: =IF(D31=$N$6,1,IF(D31=$N$5,2,IF(D31=$N$4,3,IF(D31=$N$3,4,"n/a")))) -> 1 | F31: Please add justification. | L31: Cf: Guidance
C32: Average: | D32: =IF(E32<1.5,"Low",IF(E32<2.5,"Moderate",IF(E32<3.5,"Substantial",IF(E32<4.5,"High","n/a")))) -> Low | E32: =IF(COUNT(E28:E31)=0,"n/a",AVERAGE(E28:E31)) -> 1 | F32: =E32 -> 1 | H32: Final: | I32: =D32 -> Low | J32: =IF(I32=$N$7,"n/a",IF(AND(I32=$N$5,D32=$N$6),1.5,IF(AND(I32=$N$4,D32=$N$5),2.5,IF(AND(I32=$N$3,D32=$N$4),3.5,IF(AND(I32=$N$6,D32=$N$5),1.49,IF(AND(I32=$N$5,D32=$N$4),2.49,IF(AND(I32=$N$4,D32=$N$3),3.49,E32))))))) -> 1 | K32: Justification if adjustment of the score level = …
A33: 2.3 Equity,compensation and justice
A34: 2.3.1 Do the locally applied rules promote secure and equitable tenure rights or access to land and water? | D34: n/a | E34: =IF(D34=$N$6,1,IF(D34=$N$5,2,IF(D34=$N$4,3,IF(D34=$N$3,4,"n/a")))) -> n/a | F34: Please add justification. | L34: Cf: Guidance
A35: 2.3.2 In case disruption of livelihoods is expected, have alternative strategies been considered? | D35: n/a | E35: =IF(D35=$N$6,1,IF(D35=$N$5,2,IF(D35=$N$4,3,IF(D35=$N$3,4,"n/a")))) -> n/a | F35: Please add justification.
A36: 2.3.3 Where expropriation is indispensable: is a system for ensuring fair and prompt compensation in place (in accordance with the national law and publically acknowledged as being fair)? | D36: n/a | E36: =IF(D36=$N$6,1,IF(D36=$N$5,2,IF(D36=$N$4,3,IF(D36=$N$3,4,"n/a")))) -> n/a | F36: Please add justification.
A37: 2.3.4 Are there provisions foreseen to address stakeholder complains and for arbitration of possible conflicts caused by value chain investments? | D37: n/a | E37: =IF(D37=$N$6,1,IF(D37=$N$5,2,IF(D37=$N$4,3,IF(D37=$N$3,4,"n/a")))) -> n/a | F37: Please add justification.
C38: Average: | D38: =IF(E38<1.5,"Low",IF(E38<2.5,"Moderate",IF(E38<3.5,"Substantial",IF(E38<4.5,"High","n/a")))) -> n/a | E38: =IF(COUNT(E34:E37)=0,"n/a",AVERAGE(E34:E37)) -> n/a | F38: =E38 -> n/a | H38: Final: | I38: =D38 -> n/a | J38: =IF(I38=$N$7,"n/a",IF(AND(I38=$N$5,D38=$N$6),1.5,IF(AND(I38=$N$4,D38=$N$5),2.5,IF(AND(I38=$N$3,D38=$N$4),3.5,IF(AND(I38=$N$6,D38=$N$5),1.49,IF(AND(I38=$N$5,D38=$N$4),2.49,IF(AND(I38=$N$4,D38=$N$3),3.49,E38))))))) -> n/a | K38: Justification if adjustment of the score level = …
A39: 3. GENDER EQUALITY
A40: 3.1 Economic activities
...

Sheet Guidance
A1: How to use the Social Profile Tool
A2: When using this Excel tool, please take into account the following guiding principles:
A3: * | B3: Only fill in blank cells and select score levels as they appear in the drop-down lists of the questionnaire! Grey cells are automatically filled based on previous entries. Grey cells should never be changed by the user.
A4: ** | B4: Be careful in using "copy and paste" function that covers more than one cell, as you might interfere with non-visible formulas or cells used for calculations.
A5: *** | B5: When writing comments and observation with text ending beyond the limits of the cell, you can adjust the row height by dragging down the bottom line of the row from the far left colum which shows the row numbers.
A6: It is recommended to follow the steps below:
A7: Profile sheet
A8: 1 | B8: Fill in the name of the value chain, country and the date of assessment in the first sheet "Profile". They will be copied automatically in the other sheets from where you cannot access these elements.
A9: Questionnaire sheet
A10: =+A8+1 -> 2 | B10: Respond to each question by using the score levels: - High, - Substantial, - Moderate/Low, - Not at all, - n/a = not applicable (when not relevant) or not available (when not possible to reply). In your assessment, take into account the likelihood and the impact and consider the stage of the chain the most at risk.
A11: =+A10+1 -> 3 | B11: Give a short justification for your choice in the "Comments" column.
A12: =+A11+1 -> 4 | B12: In the column "Source", you should include which source of information you used for your judgement.
A13: =+A12+1 -> 5 | B13: The "Average" score level is automatically set as the unweighted average of the score levels for the underlying questions. In exceptional cases, the average score level can be manually modified using column I (cell next to "Final:"). This may be used in order to take into account important aspects not covered by the questions. In this case, a justification should be provided (under "Comments", column K). Change can only be done to the immediate nearest score level or to n/a (otherwise the calculations will be wrong). NB: After making trials of adjustment of this cell, if you eventually want to let the initial automatic calculation work, it is necessary to reintroduce manually the reference of the corresponding D cell ("=Dx" for line x) to come back to the intial state of the spreadsheet.
A14: Register sheet
A15: =+A13+1 -> 6 | B15: Describe the major risks, if any, in column E. All the questions assessed as "not at all" or "moderate/low" in the questionnaire need to be analyzed as possible risks or negative outcomes. Major risks and negative consequences may be identified by the questionnaire, but could also include further issues to be pointed at.
A16: =+A15+1 -> 7 | B16: Describe the major mitigating measures in column F.
A17: =+A16+1 -> 8 | B17: Insert date and copy scores of previous social profile assessment (column H), if there has been one.
A18: =+A17+1 -> 9 | B18: Highlight progress done in the implementation of specific measures since previous social profile assessment in column G "Comments".
A19: Profile sheet
A20: =+A18+1 -> 10 | B20: Provide an overall summary of the key issues and recommendations, the Risk and Cost of Non-Intervention vs. Benefits and the key mitigating measures.
A21: Warning | B21: After some time of work and changes, it happens that colours are not automatically selected. => Save your work, close the file and open it again… and it will work afresh!
A24: Question n° | B24: Explanations on questions
A25: 1.2.1 | B25: Risk assessment
A26: 1.2.2 | B26: Risk assessment
A27: 1.4.1 | B27: Remuneration: provision of income allowing workers to support themselves and their families.
A28: 2.1 | B28: Consider as entry point for the analysis the current state of play of the country specific land governance (policy, legislation, institutions/actors, enacting and application of legislation in particular as regards the consideration/impact on smallholders, land administration). This is important to know/judge if government legislation and/or customary rights matter
A29: 2.1.1 | B29: How is adherence to VGGT done and is this publically acknowledged?
A30: 2.2.4 | B30: Respond 'High' if formal contract exists
A31: 2.3.1 | B31: Practice of legal recognition and allocation of land rights in the sphere of value chain investment: formal, customary and informal land rights, rights of indigenous people, pastoralists, contracts… To which extent doeas the value chain investment impact on local/traditional land governance?
A32: 3.1.1 | B32: Good reasons for restictions make the question non applicable
A33: 4 | B33: The complexity of the food and nutrition security sector implies that, for the purpose of this social profile, it should be analysed from the point of view of changes and evolution of the systems
A34: 4.1.1 | B34: Does food availability increase? Production,export Yc transports (trucks…).
A35: 4.1.2 | B35: Import, transport, stock, market institutions.
A36: 4.2.2 | B36: Impact on food prices; impact on revenues => link with Economic analysis.
A37: 4.3.2 | B37: As nutritional practices please consider: nutrition policies and strategies, nutrition-training, education, the setting up of coordination mechanisms between agriculture, health, education, and social protection sectors. Do such nutritional practises target pregnant and lactating women as well as children under five (with a stronger emphasis on those under the age of two)?
A38: 4.3.3 | B38: Minimum number of food groups consumed by an individual over a reference period. Ref.: FAO Manual Minimum Dietary Diversity in Women (in preparation). This is relevant only if the baseline score is low.
A39: 4.4.2 | B39: Price variation can be seasonal or transitory due to any type of shock.
A40: 5.1.2 | B40: Inclusiveness viewed from different perspectives: wealth strata, age, gender, ethnic or social groups…
A41: 5.2.2 | B41: Verbal agreement, long lasting collaboration, contract, market, hierarchy… Looking upstream and downstream the VC.
A42: 5.3.1 | B42: CFS RAI: principle 9 on meanigful information, consultation and decision making processes.
...
