Workbook

Sheet Study id
A1: Property | B1: Value | C1: Unit | D1: Help | E1: Description
A2: Country | B2: Zambia | C2: -
A3: Commodity | B3: Aquaculture | C3: -
A4: Reference Year | B4: 2016 | C4: -
A5: Product Type | B5: Animal products | C5: - | D5: Should be one of ‘Animal products’, ‘Orchards’ or ‘Field crops’
A6: Value chain name | B6: Aquaculture | C6: - | D6: Leave empty if data concern the whole country’s value chain, give an explicit name otherwise

Sheet Value chains description
A1: Value chain name | B1: annual volume | C1: year of volume | D1: unit | E1: Contribution volume | F1: ha | G1: Contribution area | H1: yield (t/ha)
A2: Medium-large scale systems | B2: =B5*0.78 -> 24402.3 | C2: 2016 | D2: t | E2: =B2/$B$5 -> 0.78
A3: Small-scale systems | B3: =B5*0.22 -> 6882.7 | C3: 2016 | D3: t | E3: =B3/$B$5 -> 0.22
A5: Total production | B5: =28580+2705 -> 31285 | C5: 2016 | D5: t | E5: =SUM(E2:E3) -> 1

Sheet Actor types
A1: Stage | B1: Actor type name | C1: Actor description
A2: Producers | B2: Small-scale semi-subsistence ponds | C2: Multi-species, 40-400 kg/y smallholder
A3: Producers | B3: Small-scale commercial ponds | C3: Multi-species, 1000-5000 kg/y smallholder
A4: Processors | B4: Extensive ponds/stocked water bodies | C4: <900 kg/y extensive unsupervised systems
A5: Processors | B5: Medium-scale ponds | C5: Multi-species, 20-200 t/y smallholder
A6: Processors | B6: Large-scale ponds | C6: Niloticus, 1500 t/y commercial, intensive ponds
A7: Processors | B7: Large-scale cages | C7: Niloticus, 1500-4000 t/y commercial, intensive cages
A8: Detailers | B8: Retailers | C8: Handle 2/3 of fish supply
A9: Detailers | B9: City ladies | C9: Handle some 4000 t/y, door-to-door
A10: Wholesalers | B10: Wholesalers | C10: Handle 1/3 of fish supply, including imports

Sheet Actors and Chains matrix
A1: Sub-chain | B1: Small-scale semi-subsistence ponds | C1: Small-scale commercial ponds | D1: Extensive ponds/stocked water bodies | E1: Medium-scale ponds | F1: Large-scale ponds | G1: Large-scale cages | H1: Retailers | I1: City ladies | J1: Wholesalers
A2: Medium-large scale systems | E2: X | F2: X | G2: X | H2: X | I2: X | J2: X
A3: Small-scale systems | B3: X | C3: X | D3: X | H3: X | I3: X | J3: X

Sheet Impacts
A1: LCIA method | B1: Functional Unit | C1: Impact category | D1: Sub-chain → | E1: Small-scale systems | F1: Small-scale systems | G1: Small-scale systems | H1: Small-scale systems | I1: Medium-large scale systems | J1: Medium-large scale systems | K1: Medium-large scale systems | L1: Medium-large scale systems
A2: ↓ | B2: ↓ | C2: ↓ | D2: Actor → | E2: Sub-chain total | F2: Small-scale semi-subsistence ponds | G2: Small-scale commercial ponds | H2: Extensive ponds/stocked water bodies | I2: Sub-chain total | J2: Medium-scale ponds | K2: Large-scale ponds | L2: Large-scale cages
D3: Unit ↓ | E3: Sub-chain total | F3: Small-scale semi-subsistence ponds | G3: Small-scale commercial ponds | H3: Extensive ponds/stocked water bodies | I3: Sub-chain total | J3: Medium-scale ponds | K3: Large-scale ponds | L3: Large-scale cages
A4: ReCiPe 2016 Endpoint (H) V1.08 / World (2010) H/A | B4: 1 t | C4: Human health | D4: DALY | E4: =SUM(F4:H4) -> 0.0033551933 | F4: ='sub-chains'!I21*'sub-chains'!$I$70 -> 0.0013096838 | G4: ='sub-chains'!H21*'sub-chains'!$H$70 -> 0.00032697622 | H4: ='sub-chains'!F21*'sub-chains'!$F$70 -> 0.0017185333 | I4: =SUM(J4:L4) -> 0.0060092093 | J4: ='sub-chains'!G21*'sub-chains'!$G$70 -> 0.00019043627 | K4: ='sub-chains'!E21*'sub-chains'!$E$70 -> 0.00075301791 | L4: ='sub-chains'!D21*'sub-chains'!$D$70 -> 0.0050657551
A5: ReCiPe 2016 Endpoint (H) V1.08 / World (2010) H/A | B5: 1 t | C5: Ecosystems | D5: species.yr | E5: =SUM(F5:H5) -> 3.4051956e-05 | F5: ='sub-chains'!I22*'sub-chains'!$I$70 -> 1.1598199e-05 | G5: ='sub-chains'!H22*'sub-chains'!$H$70 -> 4.8191085e-06 | H5: ='sub-chains'!F22*'sub-chains'!$F$70 -> 1.7634649e-05 | I5: =SUM(J5:L5) -> 4.5734766e-05 | J5: ='sub-chains'!G22*'sub-chains'!$G$70 -> 2.0610204e-06 | K5: ='sub-chains'!E22*'sub-chains'!$E$70 -> 7.1111462e-06 | L5: ='sub-chains'!D22*'sub-chains'!$D$70 -> 3.6562599e-05
A6: ReCiPe 2016 Endpoint (H) V1.08 / World (2010) H/A | B6: 1 t | C6: Resources | D6: USD2013 | E6: =SUM(F6:H6) -> 115.91068 | F6: ='sub-chains'!I23*'sub-chains'!$I$70 -> 43.70746 | G6: ='sub-chains'!H23*'sub-chains'!$H$70 -> 11.159962 | H6: ='sub-chains'!F23*'sub-chains'!$F$70 -> 61.043258 | I6: =SUM(J6:L6) -> 166.78591 | J6: ='sub-chains'!G23*'sub-chains'!$G$70 -> 5.0800242 | K6: ='sub-chains'!E23*'sub-chains'!$E$70 -> 20.61013 | L6: ='sub-chains'!D23*'sub-chains'!$D$70 -> 141.09576
A7: ReCiPe 2016 Endpoint (H) V1.08 / World (2010) H/A | B7: 1 t | C7: Total | D7: Pt | E7: =SUM(F7:H7) -> 65.999876 | F7: ='sub-chains'!I46*'sub-chains'!$I$70 -> 25.29375 | G7: ='sub-chains'!H46*'sub-chains'!$H$70 -> 6.8367324 | H7: ='sub-chains'!F46*'sub-chains'!$F$70 -> 33.869394 | I7: =SUM(J7:L7) -> 113.79114 | J7: ='sub-chains'!G46*'sub-chains'!$G$70 -> 3.7700484 | K7: ='sub-chains'!E46*'sub-chains'!$E$70 -> 14.630349 | L7: ='sub-chains'!D46*'sub-chains'!$D$70 -> 95.390748
A8: ReCiPe 2016 Endpoint (H) V1.08 / World (2010) H/A | B8: 1 t | C8: Human health | D8: Pt | E8: =SUM(F8:H8) -> 55.964624 | F8: ='sub-chains'!I47*'sub-chains'!$I$70 -> 21.845526 | G8: ='sub-chains'!H47*'sub-chains'!$H$70 -> 5.4539633 | H8: ='sub-chains'!F47*'sub-chains'!$F$70 -> 28.665135 | I8: =SUM(J8:L8) -> 100.23361 | J8: ='sub-chains'!G47*'sub-chains'!$G$70 -> 3.1764771 | K8: ='sub-chains'!E47*'sub-chains'!$E$70 -> 12.560339 | L8: ='sub-chains'!D47*'sub-chains'!$D$70 -> 84.496795
A9: ReCiPe 2016 Endpoint (H) V1.08 / World (2010) H/A | B9: 1 t | C9: Ecosystems | D9: Pt | E9: =SUM(F9:H9) -> 9.207649 | F9: ='sub-chains'!I48*'sub-chains'!$I$70 -> 3.1361531 | G9: ='sub-chains'!H48*'sub-chains'!$H$70 -> 1.303087 | H9: ='sub-chains'!F48*'sub-chains'!$F$70 -> 4.768409 | I9: =SUM(J9:L9) -> 12.366681 | J9: ='sub-chains'!G48*'sub-chains'!$G$70 -> 0.55729992 | K9: ='sub-chains'!E48*'sub-chains'!$E$70 -> 1.9228539 | L9: ='sub-chains'!D48*'sub-chains'!$D$70 -> 9.8865267
A10: ReCiPe 2016 Endpoint (H) V1.08 / World (2010) H/A | B10: 1 t | C10: Resources | D10: Pt | E10: =SUM(F10:H10) -> 0.82760225 | F10: ='sub-chains'!I49*'sub-chains'!$I$70 -> 0.31207126 | G10: ='sub-chains'!H49*'sub-chains'!$H$70 -> 0.079682127 | H10: ='sub-chains'!F49*'sub-chains'!$F$70 -> 0.43584886 | I10: =SUM(J10:L10) -> 1.1908514 | J10: ='sub-chains'!G49*'sub-chains'!$G$70 -> 0.036271374 | K10: ='sub-chains'!E49*'sub-chains'!$E$70 -> 0.14715634 | L10: ='sub-chains'!D49*'sub-chains'!$D$70 -> 1.0074237
A11: ReCiPe 2016 Endpoint (H) V1.08 / World (2010) H/A | B11: 1 t | C11: Global warming. Human health | D11: Pt | E11: =SUM(F11:H11) -> 25.335709 | F11: ='sub-chains'!I73*'sub-chains'!$I$70 -> 10.030899 | G11: ='sub-chains'!H73*'sub-chains'!$H$70 -> 2.805266 | H11: ='sub-chains'!F73*'sub-chains'!$F$70 -> 12.499545 | I11: =SUM(J11:L11) -> 47.892332 | J11: ='sub-chains'!G73*'sub-chains'!$G$70 -> 1.6067995 | K11: ='sub-chains'!E73*'sub-chains'!$E$70 -> 6.7965073 | L11: ='sub-chains'!D73*'sub-chains'!$D$70 -> 39.489025
A12: ReCiPe 2016 Endpoint (H) V1.08 / World (2010) H/A | B12: 1 t | C12: Global warming. Terrestrial ecosystems | D12: Pt | E12: =SUM(F12:H12) -> 1.2390058 | F12: ='sub-chains'!I74*'sub-chains'!$I$70 -> 0.49052137 | G12: ='sub-chains'!H74*'sub-chains'!$H$70 -> 0.13719829 | H12: ='sub-chains'!F74*'sub-chains'!$F$70 -> 0.6112861 | I12: =SUM(J12:L12) -> 2.3423301 | J12: ='sub-chains'!G74*'sub-chains'!$G$70 -> 0.078585012 | K12: ='sub-chains'!E74*'sub-chains'!$E$70 -> 0.3323982 | L12: ='sub-chains'!D74*'sub-chains'!$D$70 -> 1.9313469
A13: ReCiPe 2016 Endpoint (H) V1.08 / World (2010) H/A | B13: 1 t | C13: Global warming. Freshwater ecosystems | D13: Pt | E13: =SUM(F13:H13) -> 3.3846818e-05 | F13: ='sub-chains'!I75*'sub-chains'!$I$70 -> 1.3398386e-05 | G13: ='sub-chains'!H75*'sub-chains'!$H$70 -> 3.7479909e-06 | H13: ='sub-chains'!F75*'sub-chains'!$F$70 -> 1.6700441e-05 | I13: =SUM(J13:L13) -> 6.3991781e-05 | J13: ='sub-chains'!G75*'sub-chains'!$G$70 -> 2.1469309e-06 | K13: ='sub-chains'!E75*'sub-chains'!$E$70 -> 9.0811344e-06 | L13: ='sub-chains'!D75*'sub-chains'!$D$70 -> 5.2763715e-05
A14: ReCiPe 2016 Midpoint (H) V1.08 / World (2010) H | B14: 1 t | C14: Global warming | D14: kg CO2 eq | E14: =SUM(F14:H14) -> 1636.4112 | F14: ='sub-chains'!I115*'sub-chains'!$I$70 -> 647.83513 | G14: ='sub-chains'!H115*'sub-chains'!$H$70 -> 181.20051 | H14: ='sub-chains'!F115*'sub-chains'!$F$70 -> 807.37552 | I14: =SUM(J14:L14) -> 3093.6596 | J14: ='sub-chains'!G115*'sub-chains'!$G$70 -> 103.79236 | K14: ='sub-chains'!E115*'sub-chains'!$E$70 -> 439.02178 | L14: ='sub-chains'!D115*'sub-chains'!$D$70 -> 2550.8454

Sheet sub-chains
A2: Calculation: | B2: Comparer
A3: Results: | B3: Étude d'impact
A4: Product 1: | B4: 1 t Tilapia. average tilapia (du projet ACV4D_Tilapia_Zambie)
A5: Product 2: | B5: 1 t Tilapia. 200-600g. conventional. large cages. at farm gate/ZM U (du projet ACV4D_Tilapia_Zambie)
A6: Product 3: | B6: 1 t Tilapia. 200-600g. conventional. large ponds. at farm gate/ZM U (du projet ACV4D_Tilapia_Zambie)
A7: Product 4: | B7: 1 t Tilapia. 200-600g. conventional. extensive ponds. at farm gate/ZM U (du projet ACV4D_Tilapia_Zambie)
A8: Product 5: | B8: 1 t Tilapia. 200-600g. conventional. medium ponds. at farm gate/ZM U (du projet ACV4D_Tilapia_Zambie)
A9: Product 6: | B9: 1 t Tilapia. 200-600g. conventional. small commercial ponds. at farm gate/ZM U (du projet ACV4D_Tilapia_Zambie)
A10: Product 7: | B10: 1 t Tilapia. 200-600g. conventional. small subsistance ponds. at farm gate/ZM U (du projet ACV4D_Tilapia_Zambie)
A11: Méthode: | B11: ReCiPe 2016 Endpoint (H) V1.08 / World (2010) H/A
A12: Indicateur: | B12: Étude de dommages
A13: Skip categories: | B13: Jamais
... A18: Sort order: | B18: Croissant
A20: Catégorie de dommages | B20: Unité | C20: Tilapia. average tilapia | D20: Tilapia. 200-600g. conventional. large cages. at farm gate/ZM U | E20: Tilapia. 200-600g. conventional. large ponds. at farm gate/ZM U | F20: Tilapia. 200-600g. conventional. extensive ponds. at farm gate/ZM U | G20: Tilapia. 200-600g. conventional. medium ponds. at farm gate/ZM U | H20: Tilapia. 200-600g. conventional. small commercial ponds. at farm gate/ZM U | I20: Tilapia. 200-600g. conventional. small subsistance ponds. at farm gate/ZM U
A21: Human health | B21: DALY | C21: 0.0084020542 | D21: 0.0075608285 | E21: 0.0094127239 | F21: 0.021481666 | G21: 0.0063478757 | H21: 0.0046710888 | I21: 0.018709769
A22: Ecosystems | B22: species.yr | C22: 6.8298982e-05 | D22: 5.4571044e-05 | E22: 8.8889328e-05 | F22: 0.00022043311 | G22: 6.870068e-05 | H22: 6.8844407e-05 | I22: 0.00016568856
A23: Resources | B23: USD2013 | C23: 243.57509 | D23: 210.59068 | E23: 257.62663 | F23: 763.04073 | G23: 169.33414 | H23: 159.42803 | I23: 624.39229
A26: Calculation: | B26: Comparer
A27: Results: | B27: Étude d'impact
A28: Product 1: | B28: 1 t Tilapia. average tilapia (du projet ACV4D_Tilapia_Zambie)
A29: Product 2: | B29: 1 t Tilapia. 200-600g. conventional. large cages. at farm gate/ZM U (du projet ACV4D_Tilapia_Zambie)
A30: Product 3: | B30: 1 t Tilapia. 200-600g. conventional. large ponds. at farm gate/ZM U (du projet ACV4D_Tilapia_Zambie)
A31: Product 4: | B31: 1 t Tilapia. 200-600g. conventional. extensive ponds. at farm gate/ZM U (du projet ACV4D_Tilapia_Zambie)
A32: Product 5: | B32: 1 t Tilapia. 200-600g. conventional. medium ponds. at farm gate/ZM U (du projet ACV4D_Tilapia_Zambie)
A33: Product 6: | B33: 1 t Tilapia. 200-600g. conventional. small commercial ponds. at farm gate/ZM U (du projet ACV4D_Tilapia_Zambie)
A34: Product 7: | B34: 1 t Tilapia. 200-600g. conventional. small subsistance ponds. at farm gate/ZM U (du projet ACV4D_Tilapia_Zambie)
A35: Méthode: | B35: ReCiPe 2016 Endpoint (H) V1.08 / World (2010) H/A
A36: Indicateur: | B36: Score unique
A37: Skip categories: | B37: Jamais
... A43: Sort order: | B43: Croissant
A45: Catégorie de dommages | B45: Unité | C45: Tilapia. average tilapia | D45: Tilapia. 200-600g. conventional. large cages. at farm gate/ZM U | E45: Tilapia. 200-600g. conventional. large ponds. at farm gate/ZM U | F45: Tilapia. 200-600g. conventional. extensive ponds. at farm gate/ZM U | G45: Tilapia. 200-600g. conventional. medium ponds. at farm gate/ZM U | H45: Tilapia. 200-600g. conventional. small commercial ponds. at farm gate/ZM U | I45: Tilapia. 200-600g. conventional. small subsistance ponds. at farm gate/ZM U
A46: Total | B46: Pt | C46: 160.35343 | D46: 142.37425 | E46: 182.87936 | F46: 423.36742 | G46: 125.66828 | H46: 97.667605 | I46: 361.33929
A47: Human health | B47: Pt | C47: 140.14626 | D47: 126.11462 | E47: 157.00424 | F47: 358.31419 | G47: 105.88257 | H47: 77.913761 | I47: 312.07894
A48: Ecosystems | B48: Pt | C48: 18.468045 | D48: 14.75601 | E48: 24.035674 | F48: 59.605112 | G48: 18.576664 | H48: 18.615528 | I48: 44.802187
A49: Resources | B49: Pt | C49: 1.7391262 | D49: 1.5036175 | E49: 1.8394542 | F49: 5.4481108 | G49: 1.2090458 | H49: 1.1383161 | I49: 4.4581609
A52: Calculation: | B52: Comparer
A53: Results: | B53: Étude d'impact
A54: Product 1: | B54: 1 t Tilapia. average tilapia (du projet ACV4D_Tilapia_Zambie)
A55: Product 2: | B55: 1 t Tilapia. 200-600g. conventional. large cages. at farm gate/ZM U (du projet ACV4D_Tilapia_Zambie)
A56: Product 3: | B56: 1 t Tilapia. 200-600g. conventional. large ponds. at farm gate/ZM U (du projet ACV4D_Tilapia_Zambie)
...
